Workbook

Sheet _キー一覧
A1: 1
A2: 2
A3: 3
A4: 4
A5: 5
A6: 6
A7: 7
A8: 8
A9: 9
A10: 0
A11: -
A12: =
... A53: rshift

Sheet 単打
A1: 単打レイヤー
A2: シフトを押さずに、そのキーだけを打ったときのかな
A3: 使わないレイヤーは、シフトキー欄を空欄のままにしてください。そのレイヤーは無視されます。
A5: 配列名 | B5: 薙刀式 | R5: 反映済みのかな数 | Z5: =SUMPRODUCT((_対応表!$G$2:$G$4460<>"")*1) -> 155
A6: 作者 | R6: 重複しているかな | Z6: =COUNTIF(_対応表!$N$2:$N$4460,"重複") -> 0
R7: 個別指定に行がないかな | Z7: =COUNTIF(_対応表!$M$2:$M$4460,"行なし") -> 0
R8: 使用中のレイヤー数 | Z8: =SUMPRODUCT((_対応表!$B$2:$B$4460<>"")*(_対応表!$G$2:$G$4460<>"")) -> 155
A9: ■ 単打レイヤー
A10: 数字段 | F10: 1 | J10: 2 | N10: 3 | R10: 4 | V10: 5 | Z10: 6 | AD10: 7 | AH10: 8 | AL10: 9 | AP10: 0 | AT10: - | AX10: =
A12: 上段 | H12: Q | L12: W | P12: E | T12: R | X12: T | AB12: Y | AF12: U | AJ12: I | AN12: O | AR12: P | AV12: [ | AZ12: ]
L13: き | P13: て | T13: し | AJ13: る | AN13: す | AR13: へ
A14: 中段 | I14: A | M14: S | Q14: D | U14: F | Y14: G | AC14: H | AG14: J | AK14: K | AO14: L | AS14: ; | AW14: '
I15: ろ | M15: け | Q15: と | U15: か | Y15: っ | AC15: く | AG15: あ | AK15: い | AO15: う | AS15: ー
A16: 下段 | K16: Z | O16: X | S16: C | W16: V | AA16: B | AE16: N | AI16: M | AM16: , | AQ16: . | AU16: /
K17: ほ | O17: ひ | S17: は | W17: こ | AA17: そ | AE17: た | AI17: な | AM17: ん | AQ17: ら | AU17: れ
A18: 親指段 | P18: muhenkan | T18: space | AL18: henkan | AP18: kana

Sheet 2キー同時
A1: 2キー同時レイヤー
A2: シフトキー1つと文字キーの同時打鍵
A3: 使わないレイヤーは、シフトキー欄を空欄のままにしてください。そのレイヤーは無視されます。
A5: ■ 2キー同時レイヤー 01
A6: シフトキー | B6: space | G6: ← このキーと同時に押したときの、かなを下に記入します
A7: 数字段 | F7: 1 | J7: 2 | N7: 3 | R7: 4 | V7: 5 | Z7: 6 | AD7: 7 | AH7: 8 | AL7: 9 | AP7: 0 | AT7: - | AX7: =
A9: 上段 | H9: Q | L9: W | P9: E | T9: R | X9: T | AB9: Y | AF9: U | AJ9: I | AN9: O | AR9: P | AV9: [ | AZ9: ]
L10: め | P10: り | T10: ね | AF10: さ | AJ10: よ | AN10: え | AR10: ゆ
A11: 中段 | I11: A | M11: S | Q11: D | U11: F | Y11: G | AC11: H | AG11: J | AK11: K | AO11: L | AS11: ; | AW11: '
I12: せ | M12: み | Q12: に | U12: ま | Y12: ち | AC12: や | AG12: の | AK12: も | AO12: つ | AS12: ふ
A13: 下段 | K13: Z | O13: X | S13: C | W13: V | AA13: B | AE13: N | AI13: M | AM13: , | AQ13: . | AU13: /
S14: を | W14: 、 | AA14: ぬ | AE14: お | AI14: 。 | AM14: む | AQ14: わ
A15: 親指段 | P15: muhenkan | T15: space | AL15: henkan | AP15: kana
A18: ■ 2キー同時レイヤー 02
A19: シフトキー | B19: f | G19: ← このキーと同時に押したときの、かなを下に記入します
A20: 数字段 | F20: 1 | J20: 2 | N20: 3 | R20: 4 | V20: 5 | Z20: 6 | AD20: 7 | AH20: 8 | AL20: 9 | AP20: 0 | AT20: - | AX20: =
A22: 上段 | H22: Q | L22: W | P22: E | T22: R | X22: T | AB22: Y | AF22: U | AJ22: I | AN22: O | AR22: P | AV22: [ | AZ22: ]
AF23: ざ | AN23: ず | AR23: べ
A24: 中段 | I24: A | M24: S | Q24: D | U24: F | Y24: G | AC24: H | AG24: J | AK24: K | AO24: L | AS24: ; | AW24: '
AC25: ぐ | AO25: づ | AS25: ぶ
A26: 下段 | K26: Z | O26: X | S26: C | W26: V | AA26: B | AE26: N | AI26: M | AM26: , | AQ26: . | AU26: /
AE27: だ
A28: 親指段 | P28: muhenkan | T28: space | AL28: henkan | AP28: kana
A31: ■ 2キー同時レイヤー 03
A32: シフトキー | B32: j | G32: ← このキーと同時に押したときの、かなを下に記入します
A33: 数字段 | F33: 1 | J33: 2 | N33: 3 | R33: 4 | V33: 5 | Z33: 6 | AD33: 7 | AH33: 8 | AL33: 9 | AP33: 0 | AT33: - | AX33: =
A35: 上段 | H35: Q | L35: W | P35: E | T35: R | X35: T | AB35: Y | AF35: U | AJ35: I | AN35: O | AR35: P | AV35: [ | AZ35: ]
L36: ぎ | P36: で | T36: じ
A37: 中段 | I37: A | M37: S | Q37: D | U37: F | Y37: G | AC37: H | AG37: J | AK37: K | AO37: L | AS37: ; | AW37: '
I38: ぜ | M38: げ | Q38: ど | U38: が | Y38: ぢ
A39: 下段 | K39: Z | O39: X | S39: C | W39: V | AA39: B | AE39: N | AI39: M | AM39: , | AQ39: . | AU39: /
K40: ぼ | O40: び | S40: ば | W40: ご | AA40: ぞ
A41: 親指段 | P41: muhenkan | T41: space | AL41: henkan | AP41: kana
A44: ■ 2キー同時レイヤー 04
A45: シフトキー | B45: v | G45: ← このキーと同時に押したときの、かなを下に記入します
A46: 数字段 | F46: 1 | J46: 2 | N46: 3 | R46: 4 | V46: 5 | Z46: 6 | AD46: 7 | AH46: 8 | AL46: 9 | AP46: 0 | AT46: - | AX46: =
A48: 上段 | H48: Q | L48: W | P48: E | T48: R | X48: T | AB48: Y | AF48: U | AJ48: I | AN48: O | AR48: P | AV48: [ | AZ48: ]
AR49: ぺ
A50: 中段 | I50: A | M50: S | Q50: D | U50: F | Y50: G | AC50: H | AG50: J | AK50: K | AO50: L | AS50: ; | AW50: '
AS51: ぷ
...

Sheet 3キー同時
A1: 3キー同時レイヤー
A2: シフトキー2つと文字キーの同時打鍵
A3: 使わないレイヤーは、シフトキー欄を空欄のままにしてください。そのレイヤーは無視されます。
A5: ■ 3キー同時レイヤー 01
A6: シフトキー | B6: h | G6: m | L6: ← これらのキーすべてと同時に押したときの、かなを下に記入します
A7: 数字段 | F7: 1 | J7: 2 | N7: 3 | R7: 4 | V7: 5 | Z7: 6 | AD7: 7 | AH7: 8 | AL7: 9 | AP7: 0 | AT7: - | AX7: =
A9: 上段 | H9: Q | L9: W | P9: E | T9: R | X9: T | AB9: Y | AF9: U | AJ9: I | AN9: O | AR9: P | AV9: [ | AZ9: ]
A11: 中段 | I11: A | M11: S | Q11: D | U11: F | Y11: G | AC11: H | AG11: J | AK11: K | AO11: L | AS11: ; | AW11: '
A13: 下段 | K13: Z | O13: X | S13: C | W13: V | AA13: B | AE13: N | AI13: M | AM13: , | AQ13: . | AU13: /
O14: ぴゃ
A15: 親指段 | P15: muhenkan | T15: space | AL15: henkan | AP15: kana
A18: ■ 3キー同時レイヤー 02
A19: シフトキー | B19: m | G19: p | L19: ← これらのキーすべてと同時に押したときの、かなを下に記入します
A20: 数字段 | F20: 1 | J20: 2 | N20: 3 | R20: 4 | V20: 5 | Z20: 6 | AD20: 7 | AH20: 8 | AL20: 9 | AP20: 0 | AT20: - | AX20: =
A22: 上段 | H22: Q | L22: W | P22: E | T22: R | X22: T | AB22: Y | AF22: U | AJ22: I | AN22: O | AR22: P | AV22: [ | AZ22: ]
P23: てゅ
A24: 中段 | I24: A | M24: S | Q24: D | U24: F | Y24: G | AC24: H | AG24: J | AK24: K | AO24: L | AS24: ; | AW24: '
A26: 下段 | K26: Z | O26: X | S26: C | W26: V | AA26: B | AE26: N | AI26: M | AM26: , | AQ26: . | AU26: /
O27: ぴゅ
A28: 親指段 | P28: muhenkan | T28: space | AL28: henkan | AP28: kana
A31: ■ 3キー同時レイヤー 03
A32: シフトキー | B32: j | G32: h | L32: ← これらのキーすべてと同時に押したときの、かなを下に記入します
A33: 数字段 | F33: 1 | J33: 2 | N33: 3 | R33: 4 | V33: 5 | Z33: 6 | AD33: 7 | AH33: 8 | AL33: 9 | AP33: 0 | AT33: - | AX33: =
A35: 上段 | H35: Q | L35: W | P35: E | T35: R | X35: T | AB35: Y | AF35: U | AJ35: I | AN35: O | AR35: P | AV35: [ | AZ35: ]
L36: ぎゃ | T36: じゃ
A37: 中段 | I37: A | M37: S | Q37: D | U37: F | Y37: G | AC37: H | AG37: J | AK37: K | AO37: L | AS37: ; | AW37: '
Y38: ぢゃ
A39: 下段 | K39: Z | O39: X | S39: C | W39: V | AA39: B | AE39: N | AI39: M | AM39: , | AQ39: . | AU39: /
O40: びゃ
A41: 親指段 | P41: muhenkan | T41: space | AL41: henkan | AP41: kana
A44: ■ 3キー同時レイヤー 04
A45: シフトキー | B45: j | G45: i | L45: ← これらのキーすべてと同時に押したときの、かなを下に記入します
A46: 数字段 | F46: 1 | J46: 2 | N46: 3 | R46: 4 | V46: 5 | Z46: 6 | AD46: 7 | AH46: 8 | AL46: 9 | AP46: 0 | AT46: - | AX46: =
A48: 上段 | H48: Q | L48: W | P48: E | T48: R | X48: T | AB48: Y | AF48: U | AJ48: I | AN48: O | AR48: P | AV48: [ | AZ48: ]
L49: ぎょ | T49: じょ
A50: 中段 | I50: A | M50: S | Q50: D | U50: F | Y50: G | AC50: H | AG50: J | AK50: K | AO50: L | AS50: ; | AW50: '
Y51: ぢょ
A52: 下段 | K52: Z | O52: X | S52: C | W52: V | AA52: B | AE52: N | AI52: M | AM52: , | AQ52: . | AU52: /
O53: びょ
A54: 親指段 | P54: muhenkan | T54: space | AL54: henkan | AP54: kana
...

Sheet 4キー同時
A1: 4キー同時レイヤー
A2: シフトキー3つと文字キーの同時打鍵
A3: 使わないレイヤーは、シフトキー欄を空欄のままにしてください。そのレイヤーは無視されます。
A5: ■ 4キー同時レイヤー 01
A6: シフトキー | Q6: ← これらのキーすべてと同時に押したときの、かなを下に記入します
A7: 数字段 | F7: 1 | J7: 2 | N7: 3 | R7: 4 | V7: 5 | Z7: 6 | AD7: 7 | AH7: 8 | AL7: 9 | AP7: 0 | AT7: - | AX7: =
A9: 上段 | H9: Q | L9: W | P9: E | T9: R | X9: T | AB9: Y | AF9: U | AJ9: I | AN9: O | AR9: P | AV9: [ | AZ9: ]
A11: 中段 | I11: A | M11: S | Q11: D | U11: F | Y11: G | AC11: H | AG11: J | AK11: K | AO11: L | AS11: ; | AW11: '
A13: 下段 | K13: Z | O13: X | S13: C | W13: V | AA13: B | AE13: N | AI13: M | AM13: , | AQ13: . | AU13: /
A15: 親指段 | P15: muhenkan | T15: space | AL15: henkan | AP15: kana
A18: ■ 4キー同時レイヤー 02
A19: シフトキー | Q19: ← これらのキーすべてと同時に押したときの、かなを下に記入します
A20: 数字段 | F20: 1 | J20: 2 | N20: 3 | R20: 4 | V20: 5 | Z20: 6 | AD20: 7 | AH20: 8 | AL20: 9 | AP20: 0 | AT20: - | AX20: =
A22: 上段 | H22: Q | L22: W | P22: E | T22: R | X22: T | AB22: Y | AF22: U | AJ22: I | AN22: O | AR22: P | AV22: [ | AZ22: ]
A24: 中段 | I24: A | M24: S | Q24: D | U24: F | Y24: G | AC24: H | AG24: J | AK24: K | AO24: L | AS24: ; | AW24: '
A26: 下段 | K26: Z | O26: X | S26: C | W26: V | AA26: B | AE26: N | AI26: M | AM26: , | AQ26: . | AU26: /
A28: 親指段 | P28: muhenkan | T28: space | AL28: henkan | AP28: kana
A31: ■ 4キー同時レイヤー 03
A32: シフトキー | Q32: ← これらのキーすべてと同時に押したときの、かなを下に記入します
A33: 数字段 | F33: 1 | J33: 2 | N33: 3 | R33: 4 | V33: 5 | Z33: 6 | AD33: 7 | AH33: 8 | AL33: 9 | AP33: 0 | AT33: - | AX33: =
A35: 上段 | H35: Q | L35: W | P35: E | T35: R | X35: T | AB35: Y | AF35: U | AJ35: I | AN35: O | AR35: P | AV35: [ | AZ35: ]
A37: 中段 | I37: A | M37: S | Q37: D | U37: F | Y37: G | AC37: H | AG37: J | AK37: K | AO37: L | AS37: ; | AW37: '
A39: 下段 | K39: Z | O39: X | S39: C | W39: V | AA39: B | AE39: N | AI39: M | AM39: , | AQ39: . | AU39: /
A41: 親指段 | P41: muhenkan | T41: space | AL41: henkan | AP41: kana
A44: ■ 4キー同時レイヤー 04
A45: シフトキー | Q45: ← これらのキーすべてと同時に押したときの、かなを下に記入します
A46: 数字段 | F46: 1 | J46: 2 | N46: 3 | R46: 4 | V46: 5 | Z46: 6 | AD46: 7 | AH46: 8 | AL46: 9 | AP46: 0 | AT46: - | AX46: =
A48: 上段 | H48: Q | L48: W | P48: E | T48: R | X48: T | AB48: Y | AF48: U | AJ48: I | AN48: O | AR48: P | AV48: [ | AZ48: ]
A50: 中段 | I50: A | M50: S | Q50: D | U50: F | Y50: G | AC50: H | AG50: J | AK50: K | AO50: L | AS50: ; | AW50: '
A52: 下段 | K52: Z | O52: X | S52: C | W52: V | AA52: B | AE52: N | AI52: M | AM52: , | AQ52: . | AU52: /
A54: 親指段 | P54: muhenkan | T54: space | AL54: henkan | AP54: kana
A57: ■ 4キー同時レイヤー 05
A58: シフトキー | Q58: ← これらのキーすべてと同時に押したときの、かなを下に記入します
A59: 数字段 | F59: 1 | J59: 2 | N59: 3 | R59: 4 | V59: 5 | Z59: 6 | AD59: 7 | AH59: 8 | AL59: 9 | AP59: 0 | AT59: - | AX59: =
A61: 上段 | H61: Q | L61: W | P61: E | T61: R | X61: T | AB61: Y | AF61: U | AJ61: I | AN61: O | AR61: P | AV61: [ | AZ61: ]
A63: 中段 | I63: A | M63: S | Q63: D | U63: F | Y63: G | AC63: H | AG63: J | AK63: K | AO63: L | AS63: ; | AW63: '
A65: 下段 | K65: Z | O65: X | S65: C | W65: V | AA65: B | AE65: N | AI65: M | AM65: , | AQ65: . | AU65: /
A67: 親指段 | P67: muhenkan | T67: space | AL67: henkan | AP67: kana
A70: ■ 4キー同時レイヤー 06
A71: シフトキー | Q71: ← これらのキーすべてと同時に押したときの、かなを下に記入します
...

Sheet 個別指定
A1: 個別指定（正データ）
A2: キー1〜4・打鍵タイプは、各レイヤーシートから自動で反映されます（青字）。手で直接入力すると、その行は手入力が優先されます。
A3: 文字キー同士の同時打鍵（でぃ = t + l など）や連続打鍵は、ここに直接記入してください。
A5: かな | B5: グループ | C5: キー1 | D5: キー2 | E5: キー3 | F5: キー4 | G5: 打鍵タイプ | H5: 備考
A6: 【例】でぃ | B6: 外来音 | C6: t | D6: l | G6: 同時 | H6: 文字キー同士の同時打鍵（手入力）
A7: あ | B7: 清音 | C7: =IFERROR(INDEX(_対応表!$H$2:$H$4460,MATCH($A7,_対応表!$G$2:$G$4460,0)),"") -> j | D7: =IFERROR(INDEX(_対応表!$I$2:$I$4460,MATCH($A7,_対応表!$G$2:$G$4460,0)),"") | E7: =IFERROR(INDEX(_対応表!$J$2:$J$4460,MATCH($A7,_対応表!$G$2:$G$4460,0)),"") | F7: =IFERROR(INDEX(_対応表!$K$2:$K$4460,MATCH($A7,_対応表!$G$2:$G$4460,0)),"") | G7: =IFERROR(INDEX(_対応表!$L$2:$L$4460,MATCH($A7,_対応表!$G$2:$G$4460,0)),"")
A8: い | B8: 清音 | C8: =IFERROR(INDEX(_対応表!$H$2:$H$4460,MATCH($A8,_対応表!$G$2:$G$4460,0)),"") -> k | D8: =IFERROR(INDEX(_対応表!$I$2:$I$4460,MATCH($A8,_対応表!$G$2:$G$4460,0)),"") | E8: =IFERROR(INDEX(_対応表!$J$2:$J$4460,MATCH($A8,_対応表!$G$2:$G$4460,0)),"") | F8: =IFERROR(INDEX(_対応表!$K$2:$K$4460,MATCH($A8,_対応表!$G$2:$G$4460,0)),"") | G8: =IFERROR(INDEX(_対応表!$L$2:$L$4460,MATCH($A8,_対応表!$G$2:$G$4460,0)),"")
A9: う | B9: 清音 | C9: =IFERROR(INDEX(_対応表!$H$2:$H$4460,MATCH($A9,_対応表!$G$2:$G$4460,0)),"") -> l | D9: =IFERROR(INDEX(_対応表!$I$2:$I$4460,MATCH($A9,_対応表!$G$2:$G$4460,0)),"") | E9: =IFERROR(INDEX(_対応表!$J$2:$J$4460,MATCH($A9,_対応表!$G$2:$G$4460,0)),"") | F9: =IFERROR(INDEX(_対応表!$K$2:$K$4460,MATCH($A9,_対応表!$G$2:$G$4460,0)),"") | G9: =IFERROR(INDEX(_対応表!$L$2:$L$4460,MATCH($A9,_対応表!$G$2:$G$4460,0)),"")
A10: え | B10: 清音 | C10: =IFERROR(INDEX(_対応表!$H$2:$H$4460,MATCH($A10,_対応表!$G$2:$G$4460,0)),"") -> space | D10: =IFERROR(INDEX(_対応表!$I$2:$I$4460,MATCH($A10,_対応表!$G$2:$G$4460,0)),"") -> o | E10: =IFERROR(INDEX(_対応表!$J$2:$J$4460,MATCH($A10,_対応表!$G$2:$G$4460,0)),"") | F10: =IFERROR(INDEX(_対応表!$K$2:$K$4460,MATCH($A10,_対応表!$G$2:$G$4460,0)),"") | G10: =IFERROR(INDEX(_対応表!$L$2:$L$4460,MATCH($A10,_対応表!$G$2:$G$4460,0)),"") -> 同時
A11: お | B11: 清音 | C11: =IFERROR(INDEX(_対応表!$H$2:$H$4460,MATCH($A11,_対応表!$G$2:$G$4460,0)),"") -> space | D11: =IFERROR(INDEX(_対応表!$I$2:$I$4460,MATCH($A11,_対応表!$G$2:$G$4460,0)),"") -> n | E11: =IFERROR(INDEX(_対応表!$J$2:$J$4460,MATCH($A11,_対応表!$G$2:$G$4460,0)),"") | F11: =IFERROR(INDEX(_対応表!$K$2:$K$4460,MATCH($A11,_対応表!$G$2:$G$4460,0)),"") | G11: =IFERROR(INDEX(_対応表!$L$2:$L$4460,MATCH($A11,_対応表!$G$2:$G$4460,0)),"") -> 同時
A12: か | B12: 清音 | C12: =IFERROR(INDEX(_対応表!$H$2:$H$4460,MATCH($A12,_対応表!$G$2:$G$4460,0)),"") -> f | D12: =IFERROR(INDEX(_対応表!$I$2:$I$4460,MATCH($A12,_対応表!$G$2:$G$4460,0)),"") | E12: =IFERROR(INDEX(_対応表!$J$2:$J$4460,MATCH($A12,_対応表!$G$2:$G$4460,0)),"") | F12: =IFERROR(INDEX(_対応表!$K$2:$K$4460,MATCH($A12,_対応表!$G$2:$G$4460,0)),"") | G12: =IFERROR(INDEX(_対応表!$L$2:$L$4460,MATCH($A12,_対応表!$G$2:$G$4460,0)),"")
A13: き | B13: 清音 | C13: =IFERROR(INDEX(_対応表!$H$2:$H$4460,MATCH($A13,_対応表!$G$2:$G$4460,0)),"") -> w | D13: =IFERROR(INDEX(_対応表!$I$2:$I$4460,MATCH($A13,_対応表!$G$2:$G$4460,0)),"") | E13: =IFERROR(INDEX(_対応表!$J$2:$J$4460,MATCH($A13,_対応表!$G$2:$G$4460,0)),"") | F13: =IFERROR(INDEX(_対応表!$K$2:$K$4460,MATCH($A13,_対応表!$G$2:$G$4460,0)),"") | G13: =IFERROR(INDEX(_対応表!$L$2:$L$4460,MATCH($A13,_対応表!$G$2:$G$4460,0)),"")
A14: く | B14: 清音 | C14: =IFERROR(INDEX(_対応表!$H$2:$H$4460,MATCH($A14,_対応表!$G$2:$G$4460,0)),"") -> h | D14: =IFERROR(INDEX(_対応表!$I$2:$I$4460,MATCH($A14,_対応表!$G$2:$G$4460,0)),"") | E14: =IFERROR(INDEX(_対応表!$J$2:$J$4460,MATCH($A14,_対応表!$G$2:$G$4460,0)),"") | F14: =IFERROR(INDEX(_対応表!$K$2:$K$4460,MATCH($A14,_対応表!$G$2:$G$4460,0)),"") | G14: =IFERROR(INDEX(_対応表!$L$2:$L$4460,MATCH($A14,_対応表!$G$2:$G$4460,0)),"")
A15: け | B15: 清音 | C15: =IFERROR(INDEX(_対応表!$H$2:$H$4460,MATCH($A15,_対応表!$G$2:$G$4460,0)),"") -> s | D15: =IFERROR(INDEX(_対応表!$I$2:$I$4460,MATCH($A15,_対応表!$G$2:$G$4460,0)),"") | E15: =IFERROR(INDEX(_対応表!$J$2:$J$4460,MATCH($A15,_対応表!$G$2:$G$4460,0)),"") | F15: =IFERROR(INDEX(_対応表!$K$2:$K$4460,MATCH($A15,_対応表!$G$2:$G$4460,0)),"") | G15: =IFERROR(INDEX(_対応表!$L$2:$L$4460,MATCH($A15,_対応表!$G$2:$G$4460,0)),"")
A16: こ | B16: 清音 | C16: =IFERROR(INDEX(_対応表!$H$2:$H$4460,MATCH($A16,_対応表!$G$2:$G$4460,0)),"") -> v | D16: =IFERROR(INDEX(_対応表!$I$2:$I$4460,MATCH($A16,_対応表!$G$2:$G$4460,0)),"") | E16: =IFERROR(INDEX(_対応表!$J$2:$J$4460,MATCH($A16,_対応表!$G$2:$G$4460,0)),"") | F16: =IFERROR(INDEX(_対応表!$K$2:$K$4460,MATCH($A16,_対応表!$G$2:$G$4460,0)),"") | G16: =IFERROR(INDEX(_対応表!$L$2:$L$4460,MATCH($A16,_対応表!$G$2:$G$4460,0)),"")
A17: さ | B17: 清音 | C17: =IFERROR(INDEX(_対応表!$H$2:$H$4460,MATCH($A17,_対応表!$G$2:$G$4460,0)),"") -> space | D17: =IFERROR(INDEX(_対応表!$I$2:$I$4460,MATCH($A17,_対応表!$G$2:$G$4460,0)),"") -> u | E17: =IFERROR(INDEX(_対応表!$J$2:$J$4460,MATCH($A17,_対応表!$G$2:$G$4460,0)),"") | F17: =IFERROR(INDEX(_対応表!$K$2:$K$4460,MATCH($A17,_対応表!$G$2:$G$4460,0)),"") | G17: =IFERROR(INDEX(_対応表!$L$2:$L$4460,MATCH($A17,_対応表!$G$2:$G$4460,0)),"") -> 同時
A18: し | B18: 清音 | C18: =IFERROR(INDEX(_対応表!$H$2:$H$4460,MATCH($A18,_対応表!$G$2:$G$4460,0)),"") -> r | D18: =IFERROR(INDEX(_対応表!$I$2:$I$4460,MATCH($A18,_対応表!$G$2:$G$4460,0)),"") | E18: =IFERROR(INDEX(_対応表!$J$2:$J$4460,MATCH($A18,_対応表!$G$2:$G$4460,0)),"") | F18: =IFERROR(INDEX(_対応表!$K$2:$K$4460,MATCH($A18,_対応表!$G$2:$G$4460,0)),"") | G18: =IFERROR(INDEX(_対応表!$L$2:$L$4460,MATCH($A18,_対応表!$G$2:$G$4460,0)),"")
... A167: 」 | B167: 記号 | C167: =IFERROR(INDEX(_対応表!$H$2:$H$4460,MATCH($A167,_対応表!$G$2:$G$4460,0)),"") -> j | D167: =IFERROR(INDEX(_対応表!$I$2:$I$4460,MATCH($A167,_対応表!$G$2:$G$4460,0)),"") -> k | E167: =IFERROR(INDEX(_対応表!$J$2:$J$4460,MATCH($A167,_対応表!$G$2:$G$4460,0)),"") -> v | F167: =IFERROR(INDEX(_対応表!$K$2:$K$4460,MATCH($A167,_対応表!$G$2:$G$4460,0)),"") | G167: =IFERROR(INDEX(_対応表!$L$2:$L$4460,MATCH($A167,_対応表!$G$2:$G$4460,0)),"") -> 同時

Sheet _対応表
A1: シート | B1: レイヤー | C1: キーID | D1: シフト1 | E1: シフト2 | F1: シフト3 | G1: かな | H1: キー1 | I1: キー2 | J1: キー3 | K1: キー4 | L1: 打鍵タイプ | M1: 個別指定に行があるか | N1: 重複
A2: 単打 | B2: 単打 | C2: 1 | D2: ="" | E2: ="" | F2: ="" | G2: =IF(単打!F11="","",SUBSTITUTE(SUBSTITUTE(単打!F11," ","")," ","")) | H2: =IF($G2="","","1") | I2: ="" | J2: ="" | K2: ="" | L2: ="" | M2: =IF($G2="","",IF(ISNA(MATCH($G2,個別指定!$A:$A,0)),"行なし","")) | N2: =IF($G2="","",IF(COUNTIF($G$2:$G$4460,$G2)>1,"重複",""))
A3: 単打 | B3: 単打 | C3: 2 | D3: ="" | E3: ="" | F3: ="" | G3: =IF(単打!J11="","",SUBSTITUTE(SUBSTITUTE(単打!J11," ","")," ","")) | H3: =IF($G3="","","2") | I3: ="" | J3: ="" | K3: ="" | L3: ="" | M3: =IF($G3="","",IF(ISNA(MATCH($G3,個別指定!$A:$A,0)),"行なし","")) | N3: =IF($G3="","",IF(COUNTIF($G$2:$G$4460,$G3)>1,"重複",""))
A4: 単打 | B4: 単打 | C4: 3 | D4: ="" | E4: ="" | F4: ="" | G4: =IF(単打!N11="","",SUBSTITUTE(SUBSTITUTE(単打!N11," ","")," ","")) | H4: =IF($G4="","","3") | I4: ="" | J4: ="" | K4: ="" | L4: ="" | M4: =IF($G4="","",IF(ISNA(MATCH($G4,個別指定!$A:$A,0)),"行なし","")) | N4: =IF($G4="","",IF(COUNTIF($G$2:$G$4460,$G4)>1,"重複",""))
A5: 単打 | B5: 単打 | C5: 4 | D5: ="" | E5: ="" | F5: ="" | G5: =IF(単打!R11="","",SUBSTITUTE(SUBSTITUTE(単打!R11," ","")," ","")) | H5: =IF($G5="","","4") | I5: ="" | J5: ="" | K5: ="" | L5: ="" | M5: =IF($G5="","",IF(ISNA(MATCH($G5,個別指定!$A:$A,0)),"行なし","")) | N5: =IF($G5="","",IF(COUNTIF($G$2:$G$4460,$G5)>1,"重複",""))
A6: 単打 | B6: 単打 | C6: 5 | D6: ="" | E6: ="" | F6: ="" | G6: =IF(単打!V11="","",SUBSTITUTE(SUBSTITUTE(単打!V11," ","")," ","")) | H6: =IF($G6="","","5") | I6: ="" | J6: ="" | K6: ="" | L6: ="" | M6: =IF($G6="","",IF(ISNA(MATCH($G6,個別指定!$A:$A,0)),"行なし","")) | N6: =IF($G6="","",IF(COUNTIF($G$2:$G$4460,$G6)>1,"重複",""))
A7: 単打 | B7: 単打 | C7: 6 | D7: ="" | E7: ="" | F7: ="" | G7: =IF(単打!Z11="","",SUBSTITUTE(SUBSTITUTE(単打!Z11," ","")," ","")) | H7: =IF($G7="","","6") | I7: ="" | J7: ="" | K7: ="" | L7: ="" | M7: =IF($G7="","",IF(ISNA(MATCH($G7,個別指定!$A:$A,0)),"行なし","")) | N7: =IF($G7="","",IF(COUNTIF($G$2:$G$4460,$G7)>1,"重複",""))
A8: 単打 | B8: 単打 | C8: 7 | D8: ="" | E8: ="" | F8: ="" | G8: =IF(単打!AD11="","",SUBSTITUTE(SUBSTITUTE(単打!AD11," ","")," ","")) | H8: =IF($G8="","","7") | I8: ="" | J8: ="" | K8: ="" | L8: ="" | M8: =IF($G8="","",IF(ISNA(MATCH($G8,個別指定!$A:$A,0)),"行なし","")) | N8: =IF($G8="","",IF(COUNTIF($G$2:$G$4460,$G8)>1,"重複",""))
A9: 単打 | B9: 単打 | C9: 8 | D9: ="" | E9: ="" | F9: ="" | G9: =IF(単打!AH11="","",SUBSTITUTE(SUBSTITUTE(単打!AH11," ","")," ","")) | H9: =IF($G9="","","8") | I9: ="" | J9: ="" | K9: ="" | L9: ="" | M9: =IF($G9="","",IF(ISNA(MATCH($G9,個別指定!$A:$A,0)),"行なし","")) | N9: =IF($G9="","",IF(COUNTIF($G$2:$G$4460,$G9)>1,"重複",""))
A10: 単打 | B10: 単打 | C10: 9 | D10: ="" | E10: ="" | F10: ="" | G10: =IF(単打!AL11="","",SUBSTITUTE(SUBSTITUTE(単打!AL11," ","")," ","")) | H10: =IF($G10="","","9") | I10: ="" | J10: ="" | K10: ="" | L10: ="" | M10: =IF($G10="","",IF(ISNA(MATCH($G10,個別指定!$A:$A,0)),"行なし","")) | N10: =IF($G10="","",IF(COUNTIF($G$2:$G$4460,$G10)>1,"重複",""))
A11: 単打 | B11: 単打 | C11: 0 | D11: ="" | E11: ="" | F11: ="" | G11: =IF(単打!AP11="","",SUBSTITUTE(SUBSTITUTE(単打!AP11," ","")," ","")) | H11: =IF($G11="","","0") | I11: ="" | J11: ="" | K11: ="" | L11: ="" | M11: =IF($G11="","",IF(ISNA(MATCH($G11,個別指定!$A:$A,0)),"行なし","")) | N11: =IF($G11="","",IF(COUNTIF($G$2:$G$4460,$G11)>1,"重複",""))
A12: 単打 | B12: 単打 | C12: - | D12: ="" | E12: ="" | F12: ="" | G12: =IF(単打!AT11="","",SUBSTITUTE(SUBSTITUTE(単打!AT11," ","")," ","")) | H12: =IF($G12="","","-") | I12: ="" | J12: ="" | K12: ="" | L12: ="" | M12: =IF($G12="","",IF(ISNA(MATCH($G12,個別指定!$A:$A,0)),"行なし","")) | N12: =IF($G12="","",IF(COUNTIF($G$2:$G$4460,$G12)>1,"重複",""))
A13: 単打 | B13: 単打 | C13: = | D13: ="" | E13: ="" | F13: ="" | G13: =IF(単打!AX11="","",SUBSTITUTE(SUBSTITUTE(単打!AX11," ","")," ","")) | H13: =IF($G13="","","=") | I13: ="" | J13: ="" | K13: ="" | L13: ="" | M13: =IF($G13="","",IF(ISNA(MATCH($G13,個別指定!$A:$A,0)),"行なし","")) | N13: =IF($G13="","",IF(COUNTIF($G$2:$G$4460,$G13)>1,"重複",""))
A14: 単打 | B14: 単打 | C14: q | D14: ="" | E14: ="" | F14: ="" | G14: =IF(単打!H13="","",SUBSTITUTE(SUBSTITUTE(単打!H13," ","")," ","")) | H14: =IF($G14="","","q") | I14: ="" | J14: ="" | K14: ="" | L14: ="" | M14: =IF($G14="","",IF(ISNA(MATCH($G14,個別指定!$A:$A,0)),"行なし","")) | N14: =IF($G14="","",IF(COUNTIF($G$2:$G$4460,$G14)>1,"重複",""))
A15: 単打 | B15: 単打 | C15: w | D15: ="" | E15: ="" | F15: ="" | G15: =IF(単打!L13="","",SUBSTITUTE(SUBSTITUTE(単打!L13," ","")," ","")) -> き | H15: =IF($G15="","","w") -> w | I15: ="" | J15: ="" | K15: ="" | L15: ="" | M15: =IF($G15="","",IF(ISNA(MATCH($G15,個別指定!$A:$A,0)),"行なし","")) | N15: =IF($G15="","",IF(COUNTIF($G$2:$G$4460,$G15)>1,"重複",""))
A16: 単打 | B16: 単打 | C16: e | D16: ="" | E16: ="" | F16: ="" | G16: =IF(単打!P13="","",SUBSTITUTE(SUBSTITUTE(単打!P13," ","")," ","")) -> て | H16: =IF($G16="","","e") -> e | I16: ="" | J16: ="" | K16: ="" | L16: ="" | M16: =IF($G16="","",IF(ISNA(MATCH($G16,個別指定!$A:$A,0)),"行なし","")) | N16: =IF($G16="","",IF(COUNTIF($G$2:$G$4460,$G16)>1,"重複",""))
A17: 単打 | B17: 単打 | C17: r | D17: ="" | E17: ="" | F17: ="" | G17: =IF(単打!T13="","",SUBSTITUTE(SUBSTITUTE(単打!T13," ","")," ","")) -> し | H17: =IF($G17="","","r") -> r | I17: ="" | J17: ="" | K17: ="" | L17: ="" | M17: =IF($G17="","",IF(ISNA(MATCH($G17,個別指定!$A:$A,0)),"行なし","")) | N17: =IF($G17="","",IF(COUNTIF($G$2:$G$4460,$G17)>1,"重複",""))
A18: 単打 | B18: 単打 | C18: t | D18: ="" | E18: ="" | F18: ="" | G18: =IF(単打!X13="","",SUBSTITUTE(SUBSTITUTE(単打!X13," ","")," ","")) | H18: =IF($G18="","","t") | I18: ="" | J18: ="" | K18: ="" | L18: ="" | M18: =IF($G18="","",IF(ISNA(MATCH($G18,個別指定!$A:$A,0)),"行なし","")) | N18: =IF($G18="","",IF(COUNTIF($G$2:$G$4460,$G18)>1,"重複",""))
A19: 単打 | B19: 単打 | C19: y | D19: ="" | E19: ="" | F19: ="" | G19: =IF(単打!AB13="","",SUBSTITUTE(SUBSTITUTE(単打!AB13," ","")," ","")) | H19: =IF($G19="","","y") | I19: ="" | J19: ="" | K19: ="" | L19: ="" | M19: =IF($G19="","",IF(ISNA(MATCH($G19,個別指定!$A:$A,0)),"行なし","")) | N19: =IF($G19="","",IF(COUNTIF($G$2:$G$4460,$G19)>1,"重複",""))
A20: 単打 | B20: 単打 | C20: u | D20: ="" | E20: ="" | F20: ="" | G20: =IF(単打!AF13="","",SUBSTITUTE(SUBSTITUTE(単打!AF13," ","")," ","")) | H20: =IF($G20="","","u") | I20: ="" | J20: ="" | K20: ="" | L20: ="" | M20: =IF($G20="","",IF(ISNA(MATCH($G20,個別指定!$A:$A,0)),"行なし","")) | N20: =IF($G20="","",IF(COUNTIF($G$2:$G$4460,$G20)>1,"重複",""))
A21: 単打 | B21: 単打 | C21: i | D21: ="" | E21: ="" | F21: ="" | G21: =IF(単打!AJ13="","",SUBSTITUTE(SUBSTITUTE(単打!AJ13," ","")," ","")) -> る | H21: =IF($G21="","","i") -> i | I21: ="" | J21: ="" | K21: ="" | L21: ="" | M21: =IF($G21="","",IF(ISNA(MATCH($G21,個別指定!$A:$A,0)),"行なし","")) | N21: =IF($G21="","",IF(COUNTIF($G$2:$G$4460,$G21)>1,"重複",""))
A22: 単打 | B22: 単打 | C22: o | D22: ="" | E22: ="" | F22: ="" | G22: =IF(単打!AN13="","",SUBSTITUTE(SUBSTITUTE(単打!AN13," ","")," ","")) -> す | H22: =IF($G22="","","o") -> o | I22: ="" | J22: ="" | K22: ="" | L22: ="" | M22: =IF($G22="","",IF(ISNA(MATCH($G22,個別指定!$A:$A,0)),"行なし","")) | N22: =IF($G22="","",IF(COUNTIF($G$2:$G$4460,$G22)>1,"重複",""))
A23: 単打 | B23: 単打 | C23: p | D23: ="" | E23: ="" | F23: ="" | G23: =IF(単打!AR13="","",SUBSTITUTE(SUBSTITUTE(単打!AR13," ","")," ","")) -> へ | H23: =IF($G23="","","p") -> p | I23: ="" | J23: ="" | K23: ="" | L23: ="" | M23: =IF($G23="","",IF(ISNA(MATCH($G23,個別指定!$A:$A,0)),"行なし","")) | N23: =IF($G23="","",IF(COUNTIF($G$2:$G$4460,$G23)>1,"重複",""))
A24: 単打 | B24: 単打 | C24: [ | D24: ="" | E24: ="" | F24: ="" | G24: =IF(単打!AV13="","",SUBSTITUTE(SUBSTITUTE(単打!AV13," ","")," ","")) | H24: =IF($G24="","","[") | I24: ="" | J24: ="" | K24: ="" | L24: ="" | M24: =IF($G24="","",IF(ISNA(MATCH($G24,個別指定!$A:$A,0)),"行なし","")) | N24: =IF($G24="","",IF(COUNTIF($G$2:$G$4460,$G24)>1,"重複",""))
A25: 単打 | B25: 単打 | C25: ] | D25: ="" | E25: ="" | F25: ="" | G25: =IF(単打!AZ13="","",SUBSTITUTE(SUBSTITUTE(単打!AZ13," ","")," ","")) | H25: =IF($G25="","","]") | I25: ="" | J25: ="" | K25: ="" | L25: ="" | M25: =IF($G25="","",IF(ISNA(MATCH($G25,個別指定!$A:$A,0)),"行なし","")) | N25: =IF($G25="","",IF(COUNTIF($G$2:$G$4460,$G25)>1,"重複",""))
A26: 単打 | B26: 単打 | C26: a | D26: ="" | E26: ="" | F26: ="" | G26: =IF(単打!I15="","",SUBSTITUTE(SUBSTITUTE(単打!I15," ","")," ","")) -> ろ | H26: =IF($G26="","","a") -> a | I26: ="" | J26: ="" | K26: ="" | L26: ="" | M26: =IF($G26="","",IF(ISNA(MATCH($G26,個別指定!$A:$A,0)),"行なし","")) | N26: =IF($G26="","",IF(COUNTIF($G$2:$G$4460,$G26)>1,"重複",""))
A27: 単打 | B27: 単打 | C27: s | D27: ="" | E27: ="" | F27: ="" | G27: =IF(単打!M15="","",SUBSTITUTE(SUBSTITUTE(単打!M15," ","")," ","")) -> け | H27: =IF($G27="","","s") -> s | I27: ="" | J27: ="" | K27: ="" | L27: ="" | M27: =IF($G27="","",IF(ISNA(MATCH($G27,個別指定!$A:$A,0)),"行なし","")) | N27: =IF($G27="","",IF(COUNTIF($G$2:$G$4460,$G27)>1,"重複",""))
A28: 単打 | B28: 単打 | C28: d | D28: ="" | E28: ="" | F28: ="" | G28: =IF(単打!Q15="","",SUBSTITUTE(SUBSTITUTE(単打!Q15," ","")," ","")) -> と | H28: =IF($G28="","","d") -> d | I28: ="" | J28: ="" | K28: ="" | L28: ="" | M28: =IF($G28="","",IF(ISNA(MATCH($G28,個別指定!$A:$A,0)),"行なし","")) | N28: =IF($G28="","",IF(COUNTIF($G$2:$G$4460,$G28)>1,"重複",""))
A29: 単打 | B29: 単打 | C29: f | D29: ="" | E29: ="" | F29: ="" | G29: =IF(単打!U15="","",SUBSTITUTE(SUBSTITUTE(単打!U15," ","")," ","")) -> か | H29: =IF($G29="","","f") -> f | I29: ="" | J29: ="" | K29: ="" | L29: ="" | M29: =IF($G29="","",IF(ISNA(MATCH($G29,個別指定!$A:$A,0)),"行なし","")) | N29: =IF($G29="","",IF(COUNTIF($G$2:$G$4460,$G29)>1,"重複",""))
A30: 単打 | B30: 単打 | C30: g | D30: ="" | E30: ="" | F30: ="" | G30: =IF(単打!Y15="","",SUBSTITUTE(SUBSTITUTE(単打!Y15," ","")," ","")) -> っ | H30: =IF($G30="","","g") -> g | I30: ="" | J30: ="" | K30: ="" | L30: ="" | M30: =IF($G30="","",IF(ISNA(MATCH($G30,個別指定!$A:$A,0)),"行なし","")) | N30: =IF($G30="","",IF(COUNTIF($G$2:$G$4460,$G30)>1,"重複",""))
A31: 単打 | B31: 単打 | C31: h | D31: ="" | E31: ="" | F31: ="" | G31: =IF(単打!AC15="","",SUBSTITUTE(SUBSTITUTE(単打!AC15," ","")," ","")) -> く | H31: =IF($G31="","","h") -> h | I31: ="" | J31: ="" | K31: ="" | L31: ="" | M31: =IF($G31="","",IF(ISNA(MATCH($G31,個別指定!$A:$A,0)),"行なし","")) | N31: =IF($G31="","",IF(COUNTIF($G$2:$G$4460,$G31)>1,"重複",""))
A32: 単打 | B32: 単打 | C32: j | D32: ="" | E32: ="" | F32: ="" | G32: =IF(単打!AG15="","",SUBSTITUTE(SUBSTITUTE(単打!AG15," ","")," ","")) -> あ | H32: =IF($G32="","","j") -> j | I32: ="" | J32: ="" | K32: ="" | L32: ="" | M32: =IF($G32="","",IF(ISNA(MATCH($G32,個別指定!$A:$A,0)),"行なし","")) | N32: =IF($G32="","",IF(COUNTIF($G$2:$G$4460,$G32)>1,"重複",""))
A33: 単打 | B33: 単打 | C33: k | D33: ="" | E33: ="" | F33: ="" | G33: =IF(単打!AK15="","",SUBSTITUTE(SUBSTITUTE(単打!AK15," ","")," ","")) -> い | H33: =IF($G33="","","k") -> k | I33: ="" | J33: ="" | K33: ="" | L33: ="" | M33: =IF($G33="","",IF(ISNA(MATCH($G33,個別指定!$A:$A,0)),"行なし","")) | N33: =IF($G33="","",IF(COUNTIF($G$2:$G$4460,$G33)>1,"重複",""))
A34: 単打 | B34: 単打 | C34: l | D34: ="" | E34: ="" | F34: ="" | G34: =IF(単打!AO15="","",SUBSTITUTE(SUBSTITUTE(単打!AO15," ","")," ","")) -> う | H34: =IF($G34="","","l") -> l | I34: ="" | J34: ="" | K34: ="" | L34: ="" | M34: =IF($G34="","",IF(ISNA(MATCH($G34,個別指定!$A:$A,0)),"行なし","")) | N34: =IF($G34="","",IF(COUNTIF($G$2:$G$4460,$G34)>1,"重複",""))
A35: 単打 | B35: 単打 | C35: ; | D35: ="" | E35: ="" | F35: ="" | G35: =IF(単打!AS15="","",SUBSTITUTE(SUBSTITUTE(単打!AS15," ","")," ","")) -> ー | H35: =IF($G35="","",";") -> ; | I35: ="" | J35: ="" | K35: ="" | L35: ="" | M35: =IF($G35="","",IF(ISNA(MATCH($G35,個別指定!$A:$A,0)),"行なし","")) | N35: =IF($G35="","",IF(COUNTIF($G$2:$G$4460,$G35)>1,"重複",""))
A36: 単打 | B36: 単打 | C36: ' | D36: ="" | E36: ="" | F36: ="" | G36: =IF(単打!AW15="","",SUBSTITUTE(SUBSTITUTE(単打!AW15," ","")," ","")) | H36: =IF($G36="","","'") | I36: ="" | J36: ="" | K36: ="" | L36: ="" | M36: =IF($G36="","",IF(ISNA(MATCH($G36,個別指定!$A:$A,0)),"行なし","")) | N36: =IF($G36="","",IF(COUNTIF($G$2:$G$4460,$G36)>1,"重複",""))
A37: 単打 | B37: 単打 | C37: z | D37: ="" | E37: ="" | F37: ="" | G37: =IF(単打!K17="","",SUBSTITUTE(SUBSTITUTE(単打!K17," ","")," ","")) -> ほ | H37: =IF($G37="","","z") -> z | I37: ="" | J37: ="" | K37: ="" | L37: ="" | M37: =IF($G37="","",IF(ISNA(MATCH($G37,個別指定!$A:$A,0)),"行なし","")) | N37: =IF($G37="","",IF(COUNTIF($G$2:$G$4460,$G37)>1,"重複",""))
A38: 単打 | B38: 単打 | C38: x | D38: ="" | E38: ="" | F38: ="" | G38: =IF(単打!O17="","",SUBSTITUTE(SUBSTITUTE(単打!O17," ","")," ","")) -> ひ | H38: =IF($G38="","","x") -> x | I38: ="" | J38: ="" | K38: ="" | L38: ="" | M38: =IF($G38="","",IF(ISNA(MATCH($G38,個別指定!$A:$A,0)),"行なし","")) | N38: =IF($G38="","",IF(COUNTIF($G$2:$G$4460,$G38)>1,"重複",""))
A39: 単打 | B39: 単打 | C39: c | D39: ="" | E39: ="" | F39: ="" | G39: =IF(単打!S17="","",SUBSTITUTE(SUBSTITUTE(単打!S17," ","")," ","")) -> は | H39: =IF($G39="","","c") -> c | I39: ="" | J39: ="" | K39: ="" | L39: ="" | M39: =IF($G39="","",IF(ISNA(MATCH($G39,個別指定!$A:$A,0)),"行なし","")) | N39: =IF($G39="","",IF(COUNTIF($G$2:$G$4460,$G39)>1,"重複",""))
A40: 単打 | B40: 単打 | C40: v | D40: ="" | E40: ="" | F40: ="" | G40: =IF(単打!W17="","",SUBSTITUTE(SUBSTITUTE(単打!W17," ","")," ","")) -> こ | H40: =IF($G40="","","v") -> v | I40: ="" | J40: ="" | K40: ="" | L40: ="" | M40: =IF($G40="","",IF(ISNA(MATCH($G40,個別指定!$A:$A,0)),"行なし","")) | N40: =IF($G40="","",IF(COUNTIF($G$2:$G$4460,$G40)>1,"重複",""))
...

Sheet 記入方法
A1: 記入方法
A3: 1. レイヤーシート
A4: 単打 | B4: シフトなしで打ったときのかなを、キーの位置に記入します。
A5: 2キー同時 | B5: シフトキーを1つ指定し、それと同時に押したときのかなを記入。20面あります。
A6: 3キー同時 | B6: シフトキーを2つ指定。その2つ + 文字キーの3キー同時打鍵。20面。
A7: 4キー同時 | B7: シフトキーを3つ指定。その3つ + 文字キーの4キー同時打鍵。20面。
A8: 使わないレイヤー | B8: シフトキー欄を空欄のままにしてください。無視されます。
A10: 2. 個別指定シート（正データ）
A11: 自動反映 | B11: レイヤーシートの内容が青字で自動的に入ります。数式です。
A12: 手入力の優先 | B12: 青字のセルに直接入力すると、その行は手入力が優先されます。
A13: ここにしか書けないもの | B13: 文字キー同士の同時打鍵（でぃ = t + l）と、連続打鍵（が = か → 濁点キー）。
A14: 連続打鍵の書き方 | B14: キー1・キー2… に順に打つキーを入れ、打鍵タイプを「連続」にします。
A16: 3. 拗音・外来音について
A17: 分解して打つ配列 | B17: 「ゃ」にキーを割り当てれば「しゃ」は自動で2打鍵になります。記入不要です。
A18: 1打で打つ配列 | B18: 該当レイヤーの位置か、個別指定シートに記入してください。
A20: 4. 確認用の集計（単打シート右上）
A21: 反映済みのかな数 | B21: レイヤーに記入され、個別指定へ反映された数。
A22: 重複しているかな | B22: 同じかなが複数のキーに割り当てられている数。0 が理想です。
A23: 個別指定に行がないかな | B23: 一覧にないかなを記入した場合。個別指定シートに行を追加してください。
A25: 5. 親指キー
A26: space / muhenkan / henkan / kana | B26: スペース / 無変換 / 変換 / かな
A27: lshift / rshift | B27: 左右のシフトキー。記号入力などで使う場合に指定します。
A28: lthumb / rthumb | B28: 自作キーボードの左右親指キー
A29: space を押す親指 | B29: 既定は「打鍵する手と逆の親指」。親指の移動距離は指と別に集計します。

Sheet キーID一覧
A1: 使用できるキーID（QWERTY 刻印での位置）
A3: 数字段 | B3: 1 | C3: 2 | D3: 3 | E3: 4 | F3: 5 | G3: 6 | H3: 7 | I3: 8 | J3: 9 | K3: 0 | L3: - | M3: =
A4: 上段 | B4: q | C4: w | D4: e | E4: r | F4: t | G4: y | H4: u | I4: i | J4: o | K4: p | L4: [ | M4: ]
A5: 中段 | B5: a | C5: s | D5: d | E5: f | F5: g | G5: h | H5: j | I5: k | J5: l | K5: ; | L5: '
A6: 下段 | B6: z | C6: x | D6: c | E6: v | F6: b | G6: n | H6: m | I6: , | J6: . | K6: /
A8: 親指キー | B8: henkan | C8: kana | D8: lthumb | E8: muhenkan | F8: rthumb | G8: space
A9: シフトキー | B9: lshift | C9: rshift

Sheet _meta
A1: sheet | B1: layer | C1: n_shift | D1: shift_cells | E1: key | F1: input_row | G1: col
A2: 単打 | B2: 単打 | C2: 0 | E2: 1 | F2: 11 | G2: 6
A3: 単打 | B3: 単打 | C3: 0 | E3: 2 | F3: 11 | G3: 10
A4: 単打 | B4: 単打 | C4: 0 | E4: 3 | F4: 11 | G4: 14
A5: 単打 | B5: 単打 | C5: 0 | E5: 4 | F5: 11 | G5: 18
A6: 単打 | B6: 単打 | C6: 0 | E6: 5 | F6: 11 | G6: 22
A7: 単打 | B7: 単打 | C7: 0 | E7: 6 | F7: 11 | G7: 26
A8: 単打 | B8: 単打 | C8: 0 | E8: 7 | F8: 11 | G8: 30
A9: 単打 | B9: 単打 | C9: 0 | E9: 8 | F9: 11 | G9: 34
A10: 単打 | B10: 単打 | C10: 0 | E10: 9 | F10: 11 | G10: 38
A11: 単打 | B11: 単打 | C11: 0 | E11: 0 | F11: 11 | G11: 42
A12: 単打 | B12: 単打 | C12: 0 | E12: - | F12: 11 | G12: 46
A13: 単打 | B13: 単打 | C13: 0 | E13: = | F13: 11 | G13: 50
... A50: 単打 | B50: 単打 | C50: 0 | E50: kana | F50: 19 | G50: 42
A51: 2キー同時 | B51: 2キー同時-01 | C51: 1 | D51: 6:2 | E51: 1 | F51: 8 | G51: 6
A52: 2キー同時 | B52: 2キー同時-01 | C52: 1 | D52: 6:2 | E52: 2 | F52: 8 | G52: 10
A53: 2キー同時 | B53: 2キー同時-01 | C53: 1 | D53: 6:2 | E53: 3 | F53: 8 | G53: 14
A54: 2キー同時 | B54: 2キー同時-01 | C54: 1 | D54: 6:2 | E54: 4 | F54: 8 | G54: 18
A55: 2キー同時 | B55: 2キー同時-01 | C55: 1 | D55: 6:2 | E55: 5 | F55: 8 | G55: 22
A56: 2キー同時 | B56: 2キー同時-01 | C56: 1 | D56: 6:2 | E56: 6 | F56: 8 | G56: 26
A57: 2キー同時 | B57: 2キー同時-01 | C57: 1 | D57: 6:2 | E57: 7 | F57: 8 | G57: 30
A58: 2キー同時 | B58: 2キー同時-01 | C58: 1 | D58: 6:2 | E58: 8 | F58: 8 | G58: 34
A59: 2キー同時 | B59: 2キー同時-01 | C59: 1 | D59: 6:2 | E59: 9 | F59: 8 | G59: 38
A60: 2キー同時 | B60: 2キー同時-01 | C60: 1 | D60: 6:2 | E60: 0 | F60: 8 | G60: 42
A61: 2キー同時 | B61: 2キー同時-01 | C61: 1 | D61: 6:2 | E61: - | F61: 8 | G61: 46
A62: 2キー同時 | B62: 2キー同時-01 | C62: 1 | D62: 6:2 | E62: = | F62: 8 | G62: 50
... A4460: 4キー同時 | B4460: 4キー同時-30 | C4460: 3 | D4460: 383:2;383:7;383:12 | E4460: kana | F4460: 393 | G4460: 42
